Workbook

Sheet Merchants
A1: merchant_id | B1: merchant_name | C1: category | D1: region
A2: 1 | B2: Merchant_001 | C2: ecommerce | D2: South
A3: 2 | B3: Merchant_002 | C3: grocery | D3: West
A4: 3 | B4: Merchant_003 | C4: grocery | D4: East
A5: 4 | B5: Merchant_004 | C5: ecommerce | D5: East
A6: 5 | B6: Merchant_005 | C6: recharge | D6: South
A7: 6 | B7: Merchant_006 | C7: food_delivery | D7: South
A8: 7 | B8: Merchant_007 | C8: food_delivery | D8: East
A9: 8 | B9: Merchant_008 | C9: food_delivery | D9: North
A10: 9 | B10: Merchant_009 | C10: ecommerce | D10: North
A11: 10 | B11: Merchant_010 | C11: grocery | D11: West
A12: 11 | B12: Merchant_011 | C12: ecommerce | D12: North
A13: 12 | B13: Merchant_012 | C13: ecommerce | D13: East
... A41: 40 | B41: Merchant_040 | C41: entertainment | D41: South

Sheet Transactions
A1: transaction_id | B1: user_id | C1: merchant_id | D1: transaction_time | E1: amount_inr | F1: payment_method | G1: status | H1: risk_score | I1: merchant_name (VLOOKUP) | J1: category (VLOOKUP) | K1: region (VLOOKUP) | L1: classification (nested IF) | N1: VLOOKUP uses fixed range Merchants!$A$2:$D$41 with $ absolute references. IFERROR shows 'Merchant not found' for unmatched merchant_id. Nested IF rule: merchant's daily total (via SUMPRODUCT) > INR 5,000 AND region != 'East' -> 'High-Value Merchant Day'.
A2: TXN100000 | B2: 350 | C2: 16 | D2: 2026-01-29 11:13:00 | E2: 2999 | F2: Wallet | G2: captured | H2: 85 | I2: =IFERROR(VLOOKUP($C2,Merchants!$A$2:$D$41,2,FALSE),"Merchant not found") -> Merchant_016 | J2: =IFERROR(VLOOKUP($C2,Merchants!$A$2:$D$41,3,FALSE),"Merchant not found") -> bill_payment | K2: =IFERROR(VLOOKUP($C2,Merchants!$A$2:$D$41,4,FALSE),"Merchant not found") -> West | L2: =IF(AND(SUMPRODUCT(($C$2:$C$548=$C2)*(LEFT($D$2:$D$548,10)=LEFT($D2,10))*$E$2:$E$548)>5000,$K2<>"East"),"High-Value Merchant Day","Standard") -> Standard
A3: TXN100001 | B3: 287 | C3: 27 | D3: 2026-01-04 11:49:00 | E3: 49 | F3: UPI | G3: captured | H3: 79 | I3: =IFERROR(VLOOKUP($C3,Merchants!$A$2:$D$41,2,FALSE),"Merchant not found") -> Merchant_027 | J3: =IFERROR(VLOOKUP($C3,Merchants!$A$2:$D$41,3,FALSE),"Merchant not found") -> ecommerce | K3: =IFERROR(VLOOKUP($C3,Merchants!$A$2:$D$41,4,FALSE),"Merchant not found") -> North | L3: =IF(AND(SUMPRODUCT(($C$2:$C$548=$C3)*(LEFT($D$2:$D$548,10)=LEFT($D3,10))*$E$2:$E$548)>5000,$K3<>"East"),"High-Value Merchant Day","Standard") -> Standard
A4: TXN100002 | B4: 122 | C4: 11 | D4: 2026-01-24 04:59:00 | E4: 1499 | F4: Wallet | G4: captured | H4: 22 | I4: =IFERROR(VLOOKUP($C4,Merchants!$A$2:$D$41,2,FALSE),"Merchant not found") -> Merchant_011 | J4: =IFERROR(VLOOKUP($C4,Merchants!$A$2:$D$41,3,FALSE),"Merchant not found") -> ecommerce | K4: =IFERROR(VLOOKUP($C4,Merchants!$A$2:$D$41,4,FALSE),"Merchant not found") -> North | L4: =IF(AND(SUMPRODUCT(($C$2:$C$548=$C4)*(LEFT($D$2:$D$548,10)=LEFT($D4,10))*$E$2:$E$548)>5000,$K4<>"East"),"High-Value Merchant Day","Standard") -> Standard
A5: TXN100003 | B5: 92 | C5: 22 | D5: 2026-01-29 13:01:00 | E5: 49 | F5: Netbanking | G5: captured | H5: 100 | I5: =IFERROR(VLOOKUP($C5,Merchants!$A$2:$D$41,2,FALSE),"Merchant not found") -> Merchant_022 | J5: =IFERROR(VLOOKUP($C5,Merchants!$A$2:$D$41,3,FALSE),"Merchant not found") -> travel | K5: =IFERROR(VLOOKUP($C5,Merchants!$A$2:$D$41,4,FALSE),"Merchant not found") -> South | L5: =IF(AND(SUMPRODUCT(($C$2:$C$548=$C5)*(LEFT($D$2:$D$548,10)=LEFT($D5,10))*$E$2:$E$548)>5000,$K5<>"East"),"High-Value Merchant Day","Standard") -> Standard
A6: TXN100004 | B6: 343 | C6: 16 | D6: 2026-01-30 13:51:00 | E6: 99 | F6: UPI | G6: captured | H6: 34 | I6: =IFERROR(VLOOKUP($C6,Merchants!$A$2:$D$41,2,FALSE),"Merchant not found") -> Merchant_016 | J6: =IFERROR(VLOOKUP($C6,Merchants!$A$2:$D$41,3,FALSE),"Merchant not found") -> bill_payment | K6: =IFERROR(VLOOKUP($C6,Merchants!$A$2:$D$41,4,FALSE),"Merchant not found") -> West | L6: =IF(AND(SUMPRODUCT(($C$2:$C$548=$C6)*(LEFT($D$2:$D$548,10)=LEFT($D6,10))*$E$2:$E$548)>5000,$K6<>"East"),"High-Value Merchant Day","Standard") -> Standard
A7: TXN100005 | B7: 196 | C7: 3 | D7: 2026-01-06 22:06:00 | E7: 99 | F7: UPI | G7: captured | H7: 60 | I7: =IFERROR(VLOOKUP($C7,Merchants!$A$2:$D$41,2,FALSE),"Merchant not found") -> Merchant_003 | J7: =IFERROR(VLOOKUP($C7,Merchants!$A$2:$D$41,3,FALSE),"Merchant not found") -> grocery | K7: =IFERROR(VLOOKUP($C7,Merchants!$A$2:$D$41,4,FALSE),"Merchant not found") -> East | L7: =IF(AND(SUMPRODUCT(($C$2:$C$548=$C7)*(LEFT($D$2:$D$548,10)=LEFT($D7,10))*$E$2:$E$548)>5000,$K7<>"East"),"High-Value Merchant Day","Standard") -> Standard
A8: TXN100006 | B8: 236 | C8: 23 | D8: 2026-01-08 06:52:00 | E8: 99 | F8: Wallet | G8: captured | H8: 39 | I8: =IFERROR(VLOOKUP($C8,Merchants!$A$2:$D$41,2,FALSE),"Merchant not found") -> Merchant_023 | J8: =IFERROR(VLOOKUP($C8,Merchants!$A$2:$D$41,3,FALSE),"Merchant not found") -> travel | K8: =IFERROR(VLOOKUP($C8,Merchants!$A$2:$D$41,4,FALSE),"Merchant not found") -> North | L8: =IF(AND(SUMPRODUCT(($C$2:$C$548=$C8)*(LEFT($D$2:$D$548,10)=LEFT($D8,10))*$E$2:$E$548)>5000,$K8<>"East"),"High-Value Merchant Day","Standard") -> Standard
A9: TXN100007 | B9: 13 | C9: 13 | D9: 2026-01-27 07:14:00 | E9: 99 | F9: UPI | G9: captured | H9: 51 | I9: =IFERROR(VLOOKUP($C9,Merchants!$A$2:$D$41,2,FALSE),"Merchant not found") -> Merchant_013 | J9: =IFERROR(VLOOKUP($C9,Merchants!$A$2:$D$41,3,FALSE),"Merchant not found") -> travel | K9: =IFERROR(VLOOKUP($C9,Merchants!$A$2:$D$41,4,FALSE),"Merchant not found") -> East | L9: =IF(AND(SUMPRODUCT(($C$2:$C$548=$C9)*(LEFT($D$2:$D$548,10)=LEFT($D9,10))*$E$2:$E$548)>5000,$K9<>"East"),"High-Value Merchant Day","Standard") -> Standard
A10: TXN100008 | B10: 36 | C10: 18 | D10: 2026-01-11 08:55:00 | E10: 799 | F10: UPI | G10: captured | H10: 44 | I10: =IFERROR(VLOOKUP($C10,Merchants!$A$2:$D$41,2,FALSE),"Merchant not found") -> Merchant_018 | J10: =IFERROR(VLOOKUP($C10,Merchants!$A$2:$D$41,3,FALSE),"Merchant not found") -> grocery | K10: =IFERROR(VLOOKUP($C10,Merchants!$A$2:$D$41,4,FALSE),"Merchant not found") -> West | L10: =IF(AND(SUMPRODUCT(($C$2:$C$548=$C10)*(LEFT($D$2:$D$548,10)=LEFT($D10,10))*$E$2:$E$548)>5000,$K10<>"East"),"High-Value Merchant Day","Standard") -> Standard
A11: TXN100009 | B11: 348 | C11: 35 | D11: 2026-01-21 16:25:00 | E11: 299 | F11: UPI | G11: captured | H11: 42 | I11: =IFERROR(VLOOKUP($C11,Merchants!$A$2:$D$41,2,FALSE),"Merchant not found") -> Merchant_035 | J11: =IFERROR(VLOOKUP($C11,Merchants!$A$2:$D$41,3,FALSE),"Merchant not found") -> recharge | K11: =IFERROR(VLOOKUP($C11,Merchants!$A$2:$D$41,4,FALSE),"Merchant not found") -> East | L11: =IF(AND(SUMPRODUCT(($C$2:$C$548=$C11)*(LEFT($D$2:$D$548,10)=LEFT($D11,10))*$E$2:$E$548)>5000,$K11<>"East"),"High-Value Merchant Day","Standard") -> Standard
A12: TXN100010 | B12: 134 | C12: 12 | D12: 2026-01-01 03:56:00 | E12: 49 | F12: UPI | G12: captured | H12: 74 | I12: =IFERROR(VLOOKUP($C12,Merchants!$A$2:$D$41,2,FALSE),"Merchant not found") -> Merchant_012 | J12: =IFERROR(VLOOKUP($C12,Merchants!$A$2:$D$41,3,FALSE),"Merchant not found") -> ecommerce | K12: =IFERROR(VLOOKUP($C12,Merchants!$A$2:$D$41,4,FALSE),"Merchant not found") -> East | L12: =IF(AND(SUMPRODUCT(($C$2:$C$548=$C12)*(LEFT($D$2:$D$548,10)=LEFT($D12,10))*$E$2:$E$548)>5000,$K12<>"East"),"High-Value Merchant Day","Standard") -> Standard
A13: TXN100011 | B13: 306 | C13: 28 | D13: 2026-01-09 01:06:00 | E13: 2999 | F13: Card | G13: failed | H13: 44 | I13: =IFERROR(VLOOKUP($C13,Merchants!$A$2:$D$41,2,FALSE),"Merchant not found") -> Merchant_028 | J13: =IFERROR(VLOOKUP($C13,Merchants!$A$2:$D$41,3,FALSE),"Merchant not found") -> ecommerce | K13: =IFERROR(VLOOKUP($C13,Merchants!$A$2:$D$41,4,FALSE),"Merchant not found") -> South | L13: =IF(AND(SUMPRODUCT(($C$2:$C$548=$C13)*(LEFT($D$2:$D$548,10)=LEFT($D13,10))*$E$2:$E$548)>5000,$K13<>"East"),"High-Value Merchant Day","Standard") -> Standard
... A548: TXN300031 | B548: 345 | C548: 12 | D548: 2026-01-23 09:03:00 | E548: 399 | F548: Card | G548: captured | H548: 69 | I548: =IFERROR(VLOOKUP($C548,Merchants!$A$2:$D$41,2,FALSE),"Merchant not found") -> Merchant_012 | J548: =IFERROR(VLOOKUP($C548,Merchants!$A$2:$D$41,3,FALSE),"Merchant not found") -> ecommerce | K548: =IFERROR(VLOOKUP($C548,Merchants!$A$2:$D$41,4,FALSE),"Merchant not found") -> East | L548: =IF(AND(SUMPRODUCT(($C$2:$C$548=$C548)*(LEFT($D$2:$D$548,10)=LEFT($D548,10))*$E$2:$E$548)>5000,$K548<>"East"),"High-Value Merchant Day","Standard") -> Standard

Sheet HLOOKUP_Demo
A1: MDR Fee-Rate Reference Table (Horizontal Layout)
A2: Payment Method | B2: UPI | C2: Wallet | D2: Card | E2: Netbanking
A3: MDR Fee % | B3: 0.25 | C3: 0.5 | D3: 1.8 | E3: 0.9
A5: HLOOKUP Demonstration
A6: Lookup Method | B6: UPI | C6: Wallet | D6: Card | E6: Netbanking
A7: HLOOKUP Formula | B7: =HLOOKUP(B6,$B$2:$E$3,2,FALSE) -> 0.25 | C7: =HLOOKUP(C6,$B$2:$E$3,2,FALSE) -> 0.5 | D7: =HLOOKUP(D6,$B$2:$E$3,2,FALSE) -> 1.8 | E7: =HLOOKUP(E6,$B$2:$E$3,2,FALSE) -> 0.9
A8: Result | B8: =HLOOKUP(B6,$B$2:$E$3,2,FALSE) -> 0.25 | C8: =HLOOKUP(C6,$B$2:$E$3,2,FALSE) -> 0.5 | D8: =HLOOKUP(D6,$B$2:$E$3,2,FALSE) -> 1.8 | E8: =HLOOKUP(E6,$B$2:$E$3,2,FALSE) -> 0.9
A10: Design decision: MDR rates are illustrative industry approximations. UPI 0.25% (RBI-capped for small merchants), Wallet 0.50%, Card 1.80% (average interchange), Netbanking 0.90% (bank surcharge). HLOOKUP uses row_index=2 to return the fee % from the second row of the table.

Sheet Pivot_Summary
A1: Pivot Table: Total Amount & Count by Merchant x Status
B3: Column Labels
B4: captured | D4: chargeback | F4: failed | H4: Total Total Amount (INR) | I4: Total Txn Count
A5: Row Labels | B5: Total Amount (INR) | C5: Txn Count | D5: Total Amount (INR) | E5: Txn Count | F5: Total Amount (INR) | G5: Txn Count
A6: 1 | B6: 10142 | C6: 8 | F6: 299 | G6: 1 | H6: 10441 | I6: 9
A7: 2 | B7: 3640 | C7: 10 | H7: 3640 | I7: 10
A8: 3 | B8: 8084 | C8: 16 | D8: 149 | E8: 1 | H8: 8233 | I8: 17
A9: 4 | B9: 6941 | C9: 9 | H9: 6941 | I9: 9
A10: 5 | B10: 5340 | C10: 10 | F10: 499 | G10: 1 | H10: 5839 | I10: 11
A11: 6 | B11: 6637 | C11: 13 | D11: 799 | E11: 1 | H11: 7436 | I11: 14
A12: 7 | B12: 11638 | C12: 12 | D12: 1999 | E12: 1 | F12: 2297 | G12: 3 | H12: 15934 | I12: 16
A13: 8 | B13: 7086 | C13: 14 | D13: 49 | E13: 1 | F13: 299 | G13: 1 | H13: 7434 | I13: 16
A14: 9 | B14: 4485 | C14: 15 | F14: 497 | G14: 3 | H14: 4982 | I14: 18
A15: 10 | B15: 7639 | C15: 11 | D15: 5048 | E15: 2 | F15: 399 | G15: 1 | H15: 13086 | I15: 14
A16: 11 | B16: 9292 | C16: 8 | D16: 149 | E16: 1 | F16: 1499 | G16: 1 | H16: 10940 | I16: 10
A17: 12 | B17: 9389 | C17: 11 | F17: 998 | G17: 2 | H17: 10387 | I17: 13
A18: 13 | B18: 10390 | C18: 10 | D18: 4999 | E18: 1 | F18: 2999 | G18: 1 | H18: 18388 | I18: 12
A19: 14 | B19: 6189 | C19: 11 | F19: 299 | G19: 1 | H19: 6488 | I19: 12
A20: 15 | B20: 7439 | C20: 11 | F20: 399 | G20: 1 | H20: 7838 | I20: 12
A21: 16 | B21: 10183 | C21: 17 | F21: 947 | G21: 3 | H21: 11130 | I21: 20
A22: 17 | B22: 12738 | C22: 12 | F22: 299 | G22: 1 | H22: 13037 | I22: 13
A23: 18 | B23: 7089 | C23: 11 | H23: 7089 | I23: 11
A24: 19 | B24: 7239 | C24: 11 | D24: 4999 | E24: 1 | F24: 598 | G24: 2 | H24: 12836 | I24: 14
A25: 20 | B25: 4192 | C25: 8 | F25: 49 | G25: 1 | H25: 4241 | I25: 9
A26: 21 | B26: 3887 | C26: 13 | F26: 4999 | G26: 1 | H26: 8886 | I26: 14
A27: 22 | B27: 11336 | C27: 14 | F27: 1198 | G27: 2 | H27: 12534 | I27: 16
A28: 23 | B28: 1041 | C28: 9 | D28: 1999 | E28: 1 | H28: 3040 | I28: 10
A29: 24 | B29: 3438 | C29: 12 | D29: 149 | E29: 1 | H29: 3587 | I29: 13
A30: 25 | B30: 12534 | C30: 16 | D30: 2999 | E30: 1 | H30: 15533 | I30: 17
A31: 26 | B31: 2991 | C31: 9 | F31: 2197 | G31: 3 | H31: 5188 | I31: 12
A32: 27 | B32: 8038 | C32: 12 | D32: 4047 | E32: 3 | F32: 1499 | G32: 1 | H32: 13584 | I32: 16
A33: 28 | B33: 4493 | C33: 7 | D33: 1999 | E33: 1 | F33: 3048 | G33: 2 | H33: 9540 | I33: 10
A34: 29 | B34: 5686 | C34: 14 | D34: 3897 | E34: 3 | F34: 3498 | G34: 2 | H34: 13081 | I34: 19
A35: 30 | B35: 7384 | C35: 16 | F35: 499 | G35: 1 | H35: 7883 | I35: 17
A36: 31 | B36: 2640 | C36: 10 | D36: 49 | E36: 1 | F36: 2146 | G36: 4 | H36: 4835 | I36: 15
A37: 32 | B37: 2589 | C37: 11 | D37: 1999 | E37: 1 | F37: 3498 | G37: 2 | H37: 8086 | I37: 14
A38: 33 | B38: 10190 | C38: 10 | F38: 149 | G38: 1 | H38: 10339 | I38: 11
A39: 34 | B39: 9635 | C39: 15 | F39: 399 | G39: 1 | H39: 10034 | I39: 16
A40: 35 | B40: 8688 | C40: 12 | F40: 598 | G40: 2 | H40: 9286 | I40: 14
A41: 36 | B41: 11535 | C41: 15 | D41: 999 | E41: 1 | H41: 12534 | I41: 16
...

Sheet Unique_Days
A1: Qualifying Merchant-Day Totals & Classification (Top 10 Merchants)
A2: merchant_id | B2: merchant_name | C2: category | D2: region | E2: total_txn_count | F2: unique_days | G2: total_gmv_inr (INR) | H2: qualifying_days (daily > 5000) | I2: max_daily_total (INR) | J2: Classification (IF rule)
A3: 16 | B3: Merchant_016 | C3: bill_payment | D3: West | E3: 20 | F3: 15 | G3: 11130 | H3: 0 | I3: 2999 | J3: Standard
A4: 29 | B4: Merchant_029 | C4: ecommerce | D4: North | E4: 19 | F4: 13 | G4: 13081 | H4: 0 | I4: 3896 | J4: Standard
A5: 37 | B5: Merchant_037 | C5: entertainment | D5: South | E5: 19 | F5: 16 | G5: 12931 | H5: 0 | I5: 2999 | J5: Standard
A6: 9 | B6: Merchant_009 | C6: ecommerce | D6: North | E6: 18 | F6: 14 | G6: 4982 | H6: 0 | I6: 1298 | J6: Standard
A7: 3 | B7: Merchant_003 | C7: grocery | D7: East | E7: 17 | F7: 13 | G7: 8233 | H7: 0 | I7: 4999 | J7: Standard
A8: 25 | B8: Merchant_025 | C8: travel | D8: South | E8: 17 | F8: 11 | G8: 15533 | H8: 0 | I8: 4498 | J8: Standard
A9: 30 | B9: Merchant_030 | C9: travel | D9: West | E9: 17 | F9: 13 | G9: 7883 | H9: 0 | I9: 2497 | J9: Standard
A10: 7 | B10: Merchant_007 | C10: food_delivery | D10: East | E10: 16 | F10: 11 | G10: 15934 | H10: 0 | I10: 4498 | J10: Standard
A11: 8 | B11: Merchant_008 | C11: food_delivery | D11: North | E11: 16 | F11: 13 | G11: 7434 | H11: 0 | I11: 2999 | J11: Standard
A12: 22 | B12: Merchant_022 | C12: travel | D12: South | E12: 16 | F12: 11 | G12: 12534 | H12: 1 | I12: 5798 | J12: High-Value Merchant Day
A14: Nested IF/AND Classification Rule: 'High-Value Merchant Day' when merchant's DAILY transaction total (sum of all txns for that merchant on that day) > INR 5,000 AND region != 'East'. 'qualifying_days' counts how many calendar days exceeded this threshold. 'max_daily_total' shows the highest single-day total for the merchant.
